# 捕获与抛出

## 1.try-catch-finally

在Java中，凡是可能抛出异常的语句，都可以用`try ... catch`捕获。把可能发生异常的语句放在`try { ... }`中，然后使用`catch`捕获对应的`Exception`及其子类。

例如下面的代码：

```java
import java.io.File;
import java.io.FileInputStream;
import java.io.FileNotFoundException;
 
public class Main {
    public static void main(String[] args) {
        File f= new File("d:/a.txt");
        try {
            System.out.println("打开 d:/a.txt");
            new FileInputStream(f);
            System.out.println("成功打开");
        } catch(FileNotFoundException e){  //可以换成Exception e
            System.out.println("d:/a.txt不存在");
            e.printStackTrace();
        }
    }
}
```

### 1.1 多catch语句

可以使用多个`catch`语句，每个`catch`分别捕获对应的`Exception`及其子类。JVM在捕获到异常后，会从上到下匹配`catch`语句，匹配到某个`catch`后，执行`catch`代码块，然后*不再*继续匹配。

简单地说就是：多个`catch`语句只有一个能被执行。例如：

```java
public static void main(String[] args) {
    try {
        process1();
        process2();
        process3();
    } catch (IOException e) {
        System.out.println(e);
    } catch (NumberFormatException e) {
        System.out.println(e);
    }
}
```

存在多个`catch`的时候，`catch`的顺序非常重要：子类必须写在前面。例如：

```java
public static void main(String[] args) {
    try {
        process1();
        process2();
        process3();
    } catch (IOException e) {
        System.out.println("IO error");
    } catch (UnsupportedEncodingException e) { // 永远捕获不到
        System.out.println("Bad encoding");
    }
}
```

对于上面的代码，`UnsupportedEncodingException`异常是永远捕获不到的，因为它是`IOException`的子类。当抛出`UnsupportedEncodingException`异常时，会被`catch (IOException e) { ... }`捕获并执行。

因此，正确的写法是把子类放到前面：

```java
public static void main(String[] args) {
    try {
        process1();
        process2();
        process3();
    } catch (UnsupportedEncodingException e) {
        System.out.println("Bad encoding");
    } catch (IOException e) {
        System.out.println("IO error");
    }
}
```

### 1.2 捕获多种异常

如果某些异常的处理逻辑相同，但是异常本身不存在继承关系，那么就得编写多条`catch`子句：

```java
public static void main(String[] args) {
    try {
        process1();
        process2();
        process3();
    } catch (IOException e) {
        System.out.println("Bad input");
    } catch (NumberFormatException e) {
        System.out.println("Bad input");
    } catch (Exception e) {
        System.out.println("Unknown error");
    }
}
```

因为处理`IOException`和`NumberFormatException`的代码是相同的，所以我们可以把它两用`|`合并到一起：

```java
public static void main(String[] args) {
    try {
        process1();
        process2();
        process3();
    } catch (IOException | NumberFormatException e) { // IOException或NumberFormatException
        System.out.println("Bad input");
    } catch (Exception e) {
        System.out.println("Unknown error");
    }
}
```

这种方式从 JDK7开始支持，好处是捕捉的代码**更紧凑**，不足之处是，一旦发生异常，**不能确定到底是哪种异常**，需要通过`instanceof` 进行判断具体的异常类型。

```java
if (e instanceof IOException)
	System.out.println("IO异常");
if (e instanceof NumberFormatException)
	System.out.println("格式解析异常");
```

### 1.3 finally语句

无论是否有异常发生，如果我们都希望执行一些语句，例如清理工作或者关闭一些资源。

可以把执行语句写若干遍：正常执行的放到`try`中，每个`catch`再写一遍。例如：

```java
public static void main(String[] args) {
    try {
        process1();
        process2();
        process3();
        System.out.println("END");
    } catch (UnsupportedEncodingException e) {
        System.out.println("Bad encoding");
        System.out.println("END");
    } catch (IOException e) {
        System.out.println("IO error");
        System.out.println("END");
    }
}
```

上述代码无论是否发生异常，都会执行`System.out.println("END");`这条语句。

那么如何消除这些重复的代码？Java的`try ... catch`机制还提供了`finally`语句，`finally`语句块**保证有无错误都会执行**。上述代码可以改写如下：

```java
public static void main(String[] args) {
    try {
        process1();
        process2();
        process3();
    } catch (UnsupportedEncodingException e) {
        System.out.println("Bad encoding");
    } catch (IOException e) {
        System.out.println("IO error");
    } finally {
        System.out.println("END");
    }
}
```

注意`finally`有几个特点：

1. `finally`语句不是必须的，可写可不写；
2. `finally`总是最后执行。

如果没有发生异常，就正常执行`try { ... }`语句块，然后执行`finally`。如果发生了异常，就中断执行`try { ... }`语句块，然后跳转执行匹配的`catch`语句块，最后执行`finally`。

可见，`finally`是用来保证一些代码必须执行的。

某些情况下，可以没有`catch`，只使用`try ... finally`结构。例如：

```
void process(String file) throws IOException {
    try {
        ...
    } finally {
        System.out.println("END");
    }
}
```

因为方法声明了可能抛出的异常，所以可以不写`catch`。

### 1.4 小结

使用`try ... catch ... finally`时：

- 多个`catch`语句的匹配顺序非常重要，子类必须放在前面；
- `finally`语句保证了有无异常都会执行，它是可选的；
- 一个`catch`语句也可以匹配多个非继承关系的异常。

## 2.throw和throws

### 2.1 异常的传播

当某个方法抛出了异常时，如果当前方法没有捕获异常，异常就会被抛到上层调用方法，直到遇到某个`try ... catch`被捕获为止：

```java
// exception
public class Main {
    public static void main(String[] args) {
        try {
            process1();
        } catch (Exception e) {
            e.printStackTrace();
        }
    }

    static void process1() {
        process2();
    }

    static void process2() {
        Integer.parseInt(null); // 会抛出NumberFormatException
    }
}
```

通过`printStackTrace()`可以打印出方法的调用栈，类似：

```java
java.lang.NumberFormatException: null
    at java.base/java.lang.Integer.parseInt(Integer.java:614)
    at java.base/java.lang.Integer.parseInt(Integer.java:770)
    at Main.process2(Main.java:16)
    at Main.process1(Main.java:12)
    at Main.main(Main.java:5)
```

`printStackTrace()`对于调试错误非常有用，上述信息表示：`NumberFormatException`是在`java.lang.Integer.parseInt`方法中被抛出的，从下往上看，调用层次依次是：

1. `main()`调用`process1()`；
2. `process1()`调用`process2()`；
3. `process2()`调用`Integer.parseInt(String)`；
4. `Integer.parseInt(String)`调用`Integer.parseInt(String, int)`。

查看`Integer.java`源码可知，抛出异常的方法代码如下：

```java
public static int parseInt(String s, int radix) throws NumberFormatException {
    if (s == null) {
        throw new NumberFormatException("null");
    }
    ...
}
```

并且，每层调用均给出了源代码的行号，可直接定位。

### 2.2 抛出异常

当发生错误时，例如，用户输入了非法的字符，我们就可以抛出异常。

通俗来说，异常抛出需要考虑如下情况：

- 主方法调用`method1`
- `method1`调用`method2`
- `method2`中处理某个任务（如打开文件）

`method2`中需要进行异常处理，但是`method2`不打算处理，而是把这个异常通过`throws`抛出去

那么`method1`就会接到该异常。 处理办法也是两种，要么是`try-catch`处理掉，要么也是抛出去。

`method1`选择本地`try-catch`住 一旦`try-catch`住了，就相当于把这个异常消化掉了，主方法在调用`method1`的时候，就不需要进行异常处理了。

如何抛出异常？参考`Integer.parseInt()`方法，抛出异常分两步：

1. 创建某个`Exception`的实例；
2. 用`throw`语句抛出。

下面是一个例子：

```java
void process2(String s) {
    if (s==null) {
        NullPointerException e = new NullPointerException();
        throw e;
    }
}
```

实际上，绝大部分抛出异常的代码都会合并写成一行：

```java
void process2(String s) {
    if (s==null) {
        throw new NullPointerException();
    }
}
```

如果一个方法捕获了某个异常后，又在`catch`子句中抛出新的异常，就相当于把抛出的异常类型“转换”了：

```java
void process1(String s) {
    try {
        process2();
    } catch (NullPointerException e) {
        throw new IllegalArgumentException();
    }
}

void process2(String s) {
    if (s==null) {
        throw new NullPointerException();
    }
}
```

当`process2()`抛出`NullPointerException`后，被`process1()`捕获，然后抛出`IllegalArgumentException()`。

如果在`main()`中捕获`IllegalArgumentException`，我们看看打印的异常栈：

```java
// exception
public class Main {
    public static void main(String[] args) {
        try {
            process1();
        } catch (Exception e) {
            e.printStackTrace();
        }
    }

    static void process1() {
        try {
            process2();
        } catch (NullPointerException e) {
            throw new IllegalArgumentException();
        }
    }

    static void process2() {
        throw new NullPointerException();
    }
}
```

打印出的异常栈类似：

```java
java.lang.IllegalArgumentException
    at Main.process1(Main.java:15)
    at Main.main(Main.java:5)
```

这说明新的异常丢失了原始异常信息，我们已经看不到原始异常`NullPointerException`的信息了。

为了能追踪到完整的异常栈，在构造异常的时候，把原始的`Exception`实例传进去，新的`Exception`就可以持有原始`Exception`信息。对上述代码改进如下：

```java
// exception
public class Main {
    public static void main(String[] args) {
        try {
            process1();
        } catch (Exception e) {
            e.printStackTrace();
        }
    }

    static void process1() {
        try {
            process2();
        } catch (NullPointerException e) {
            throw new IllegalArgumentException(e);
        }
    }

    static void process2() {
        throw new NullPointerException();
    }
}
```

运行上述代码，打印出的异常栈类似：

```
java.lang.IllegalArgumentException: java.lang.NullPointerException
    at Main.process1(Main.java:15)
    at Main.main(Main.java:5)
Caused by: java.lang.NullPointerException
    at Main.process2(Main.java:20)
    at Main.process1(Main.java:13)
```

注意到`Caused by: Xxx`，说明捕获的`IllegalArgumentException`并不是造成问题的根源，根源在于`NullPointerException`，是在`Main.process2()`方法抛出的。

在代码中获取原始异常可以使用`Throwable.getCause()`方法。如果返回`null`，说明已经是“根异常”了。

有了完整的异常栈的信息，我们才能快速定位并修复代码的问题。

因此，捕获到异常并再次抛出时，一定要留住原始异常，否则很难定位第一案发现场！

如果我们在`try`或者`catch`语句块中抛出异常，`finally`语句是否会执行？例如：

```java
// exception
public class Main {
    public static void main(String[] args) {
        try {
            Integer.parseInt("abc");
        } catch (Exception e) {
            System.out.println("catched");
            throw new RuntimeException(e);
        } finally {
            System.out.println("finally");
        }
    }
}
```

上述代码执行结果如下：

```java
catched
finally
Exception in thread "main" java.lang.RuntimeException: java.lang.NumberFormatException: For input string: "abc"
    at Main.main(Main.java:8)
Caused by: java.lang.NumberFormatException: For input string: "abc"
    at ...
```

第一行打印了`catched`，说明进入了`catch`语句块。第二行打印了`finally`，说明执行了`finally`语句块。

因此，在`catch`中抛出异常，不会影响`finally`的执行。JVM会先执行`finally`，然后抛出异常。

### 2.3 throw和throws的区别

throws与throw这两个关键字接近，不过意义不一样，有如下区别：

- throws 出现在方法声明上，而throw通常都出现在方法体内。
- throws 表示出现异常的一种可能性，并不一定会发生这些异常；throw则是抛出了异常，执行throw则一定抛出了某个异常对象。

| 不同     | throw                                                        | throws                                                       |
| -------- | ------------------------------------------------------------ | ------------------------------------------------------------ |
| 定义     | Java关键字throw 用来在函数或者代码块中显式抛出一个异常       | Java throws 关键字用在方法签名上来声明一个异常，这个方法的代码在执行时有可能会抛出这个异常。 |
| 异常类型 | 使用throw关键字的异常类型，我们只能传播非检查型异常，即，仅使用throw不能传播检查型异常 | 使用throws关键字，我们可以声明检查型和非检查型的异常。但是，throws关键字只能用于传播检查型的异常 |
| 语法     | throw 关键字后紧跟的是将要被抛出了异常的一个实例             | throws 后面紧跟着的是要被抛出了异常的类的名字                |
| 位置     | 被用在方法里面                                               | 被用在方法签名上                                             |
| 内部执行 | 我们一次只能抛出一个异常，也就是说我们不能同时抛出多个异常   | 我们可以用throws关键字同时声明多个可能会被该方法抛出的异常，比如main() throws IOException, SQLException. |

**Java throw 例子：**

**TestThrow.java**

```java
public class TestThrow {  
    //defining a method  
    public static void checkNum(int num) {  
        if (num < 1) {  
            throw new ArithmeticException("\nNumber is negative, cannot calculate square");  
        }  
        else {  
            System.out.println("Square of " + num + " is " + (num*num));  
        }  
    }  
    //main method  
    public static void main(String[] args) {  
            TestThrow obj = new TestThrow();  
            obj.checkNum(-3);  
            System.out.println("Rest of the code..");  
    }  
}
```

输出：

```text
Exception in thread "main" java.lang.ArithmeticException: 
Number is negative, cannot calculate square
    at Test_Lzw.exceptionTest.TestThrow.checkNum(TestThrow.java:7)
    at Test_Lzw.exceptionTest.TestThrow.main(TestThrow.java:16)
```

**Java throws 例子：**

**TestThrows.java**

```java
public class TestThrows {  
    //defining a method  
    public static int divideNum(int m, int n) throws ArithmeticException {  
        int div = m / n;  
        return div;  
    }  
    //main method  
    public static void main(String[] args) {  
        TestThrows obj = new TestThrows();  
        try {  
            System.out.println(obj.divideNum(45, 0));  
        }  
        catch (ArithmeticException e){  
            System.out.println("\nNumber cannot be divided by 0");  
        }  

        System.out.println("Rest of the code..");  
    }  
}
```

输出：

```text
Number cannot be divided by 0
Rest of the code..
```

**Java throw 和 throws 的例子：**

**TestThrowAndThrows.java**

```java
public class TestThrowAndThrows  
{  
    // defining a user-defined method  
    // which throws ArithmeticException  
    static void method() throws ArithmeticException  
    {  
        System.out.println("Inside the method()");  
        throw new ArithmeticException("throwing ArithmeticException");  
    }  
    //main method  
    public static void main(String args[])  
    {  
        try  
        {  
            method();  
        }  
        catch(ArithmeticException e)  
        {  
            System.out.println("caught in main() method");  
        }  
    }  
}
```

输出：

```text
Inside the method()
caught in main() method
```

### 2.4 异常屏蔽

如果在执行`finally`语句时抛出异常，那么，`catch`语句的异常还能否继续抛出？例如：

```java
// exception
public class Main {
    public static void main(String[] args) {
        try {
            Integer.parseInt("abc");
        } catch (Exception e) {
            System.out.println("catched");
            throw new RuntimeException(e);
        } finally {
            System.out.println("finally");
            throw new IllegalArgumentException();
        }
    }
}
```

执行上述代码，发现异常信息如下：

```java
catched
finally
Exception in thread "main" java.lang.IllegalArgumentException
    at Main.main(Main.java:11)
```

这说明`finally`抛出异常后，原来在`catch`中准备抛出的异常就“消失”了，因为只能抛出一个异常。没有被抛出的异常称为“被屏蔽”的异常（Suppressed Exception）。

在极少数的情况下，我们需要获知所有的异常。如何保存所有的异常信息？方法是先用`origin`变量保存原始异常，然后调用`Throwable.addSuppressed()`，把原始异常添加进来，最后在`finally`抛出：

```java
// exception
public class Main {
    public static void main(String[] args) throws Exception {
        Exception origin = null;
        try {
            System.out.println(Integer.parseInt("abc"));
        } catch (Exception e) {
            origin = e;
            throw e;
        } finally {
            Exception e = new IllegalArgumentException();
            if (origin != null) {
                e.addSuppressed(origin);
            }
            throw e;
        }
    }
}
```

当`catch`和`finally`都抛出了异常时，虽然`catch`的异常被屏蔽了，但是，`finally`抛出的异常仍然包含了它：

```java
Exception in thread "main" java.lang.IllegalArgumentException
    at Main.main(Main.java:11)
Suppressed: java.lang.NumberFormatException: For input string: "abc"
    at java.base/java.lang.NumberFormatException.forInputString(NumberFormatException.java:65)
    at java.base/java.lang.Integer.parseInt(Integer.java:652)
    at java.base/java.lang.Integer.parseInt(Integer.java:770)
    at Main.main(Main.java:6)
```

通过`Throwable.getSuppressed()`可以获取所有的`Suppressed Exception`。

绝大多数情况下，在`finally`中不要抛出异常。因此，我们通常不需要关心`Suppressed Exception`。

### 2.5 高效提问：记得贴出异常

异常打印的详细的栈信息是找出问题的关键，许多初学者在提问时只贴代码，不贴异常，相当于只报案不给线索，福尔摩斯也无能为力。

还有的童鞋只贴部分异常信息，最关键的`Caused by: xxx`给省略了，这都属于不正确的提问方式，得改。

### 2.6 小结

调用`printStackTrace()`可以打印异常的传播栈，对于调试非常有用；

捕获异常并再次抛出新的异常时，应该持有原始异常信息；

通常不要在`finally`中抛出异常。如果在`finally`中抛出异常，应该原始异常加入到原有异常中。调用方可通过`Throwable.getSuppressed()`获取所有添加的`Suppressed Exception`。